[2023-12-02 17:19:07,284] {taskinstance.py:1179} INFO - Dependencies all met for <TaskInstance: ETL_toll_data.extract_data_from_fixed_width manual__2023-12-02T17:19:04.378967+00:00 [queued]>
[2023-12-02 17:19:07,312] {taskinstance.py:1179} INFO - Dependencies all met for <TaskInstance: ETL_toll_data.extract_data_from_fixed_width manual__2023-12-02T17:19:04.378967+00:00 [queued]>
[2023-12-02 17:19:07,313] {taskinstance.py:1376} INFO - 
--------------------------------------------------------------------------------
[2023-12-02 17:19:07,313] {taskinstance.py:1377} INFO - Starting attempt 1 of 2
[2023-12-02 17:19:07,313] {taskinstance.py:1378} INFO - 
--------------------------------------------------------------------------------
[2023-12-02 17:19:07,335] {taskinstance.py:1397} INFO - Executing <Task(BashOperator): extract_data_from_fixed_width> on 2023-12-02 17:19:04.378967+00:00
[2023-12-02 17:19:07,367] {standard_task_runner.py:52} INFO - Started process 1951 to run task
[2023-12-02 17:19:07,385] {standard_task_runner.py:79} INFO - Running: ['***', 'tasks', 'run', 'ETL_toll_data', 'extract_data_from_fixed_width', 'manual__2023-12-02T17:19:04.378967+00:00', '--job-id', '2', '--raw', '--subdir', 'DAGS_FOLDER/finalassignment/staging/ETL_toll_data.py', '--cfg-path', '/tmp/tmpu__uywf9', '--error-file', '/tmp/tmpwco097q5']
[2023-12-02 17:19:07,385] {standard_task_runner.py:80} INFO - Job 2: Subtask extract_data_from_fixed_width
[2023-12-02 17:19:07,828] {task_command.py:371} INFO - Running <TaskInstance: ETL_toll_data.extract_data_from_fixed_width manual__2023-12-02T17:19:04.378967+00:00 [running]> on host 701c67987407
[2023-12-02 17:19:08,302] {taskinstance.py:1591} INFO - Exporting the following env vars:
AIRFLOW_CTX_DAG_EMAIL=oussama@gmail.com
AIRFLOW_CTX_DAG_OWNER=Oussama Ghandour
AIRFLOW_CTX_DAG_ID=ETL_toll_data
AIRFLOW_CTX_TASK_ID=extract_data_from_fixed_width
AIRFLOW_CTX_EXECUTION_DATE=2023-12-02T17:19:04.378967+00:00
AIRFLOW_CTX_TRY_NUMBER=1
AIRFLOW_CTX_DAG_RUN_ID=manual__2023-12-02T17:19:04.378967+00:00
[2023-12-02 17:19:08,304] {subprocess.py:62} INFO - Tmp dir root location: 
 /tmp
[2023-12-02 17:19:08,305] {subprocess.py:74} INFO - Running command: ['bash', '-c', 'awk `{print $10, $11}` /home/project/***/dags/finalassignment/staging/payment-data.txt > /home/project/***/dags/finalassignment/staging/fixed_width_data.csv']
[2023-12-02 17:19:08,384] {subprocess.py:85} INFO - Output:
[2023-12-02 17:19:08,388] {subprocess.py:92} INFO - bash: line 1: {print: command not found
[2023-12-02 17:19:08,402] {subprocess.py:92} INFO - awk: 1: unexpected character '.'
[2023-12-02 17:19:08,404] {subprocess.py:96} INFO - Command exited with return code 2
[2023-12-02 17:19:08,469] {taskinstance.py:1909} ERROR - Task failed with exception
Traceback (most recent call last):
  File "/home/airflow/.local/lib/python3.7/site-packages/airflow/operators/bash.py", line 195, in execute
    f'Bash command failed. The command returned a non-zero exit code {result.exit_code}.'
airflow.exceptions.AirflowException: Bash command failed. The command returned a non-zero exit code 2.
[2023-12-02 17:19:08,483] {taskinstance.py:1420} INFO - Marking task as UP_FOR_RETRY. dag_id=ETL_toll_data, task_id=extract_data_from_fixed_width, execution_date=20231202T171904, start_date=20231202T171907, end_date=20231202T171908
[2023-12-02 17:19:08,530] {warnings.py:110} WARNING - /home/***/.local/lib/python3.7/site-packages/***/utils/email.py:119: PendingDeprecationWarning: Fetching SMTP credentials from configuration variables will be deprecated in a future release. Please set credentials using a connection instead.
  send_mime_email(e_from=mail_from, e_to=recipients, mime_msg=msg, conn_id=conn_id, dryrun=dryrun)

[2023-12-02 17:19:08,530] {configuration.py:552} WARNING - section/key [smtp/smtp_user] not found in config
[2023-12-02 17:19:08,530] {email.py:228} INFO - Email alerting: attempt 1
[2023-12-02 17:19:08,561] {configuration.py:552} WARNING - section/key [smtp/smtp_user] not found in config
[2023-12-02 17:19:08,562] {email.py:228} INFO - Email alerting: attempt 1
[2023-12-02 17:19:08,562] {taskinstance.py:1964} ERROR - Failed to send email to: ['oussama@gmail.com']
Traceback (most recent call last):
  File "/home/airflow/.local/lib/python3.7/site-packages/airflow/models/taskinstance.py", line 1471, in _run_raw_task
    self._execute_task_with_callbacks(context, test_mode)
  File "/home/airflow/.local/lib/python3.7/site-packages/airflow/models/taskinstance.py", line 1618, in _execute_task_with_callbacks
    result = self._execute_task(context, task_orig)
  File "/home/airflow/.local/lib/python3.7/site-packages/airflow/models/taskinstance.py", line 1679, in _execute_task
    result = execute_callable(context=context)
  File "/home/airflow/.local/lib/python3.7/site-packages/airflow/operators/bash.py", line 195, in execute
    f'Bash command failed. The command returned a non-zero exit code {result.exit_code}.'
airflow.exceptions.AirflowException: Bash command failed. The command returned a non-zero exit code 2.

During handling of the above exception, another exception occurred:

Traceback (most recent call last):
  File "/home/airflow/.local/lib/python3.7/site-packages/airflow/models/taskinstance.py", line 2346, in email_alert
    send_email(task.email, subject, html_content)
  File "/home/airflow/.local/lib/python3.7/site-packages/airflow/utils/email.py", line 71, in send_email
    **kwargs,
  File "/home/airflow/.local/lib/python3.7/site-packages/airflow/utils/email.py", line 119, in send_email_smtp
    send_mime_email(e_from=mail_from, e_to=recipients, mime_msg=msg, conn_id=conn_id, dryrun=dryrun)
  File "/home/airflow/.local/lib/python3.7/site-packages/airflow/utils/email.py", line 230, in send_mime_email
    smtp_conn = _get_smtp_connection(smtp_host, smtp_port, smtp_timeout, smtp_ssl)
  File "/home/airflow/.local/lib/python3.7/site-packages/airflow/utils/email.py", line 264, in _get_smtp_connection
    else smtplib.SMTP(host=host, port=port, timeout=timeout)
  File "/usr/local/lib/python3.7/smtplib.py", line 251, in __init__
    (code, msg) = self.connect(host, port)
  File "/usr/local/lib/python3.7/smtplib.py", line 336, in connect
    self.sock = self._get_socket(host, port, self.timeout)
  File "/usr/local/lib/python3.7/smtplib.py", line 307, in _get_socket
    self.source_address)
  File "/usr/local/lib/python3.7/socket.py", line 728, in create_connection
    raise err
  File "/usr/local/lib/python3.7/socket.py", line 716, in create_connection
    sock.connect(sa)
OSError: [Errno 99] Cannot assign requested address

During handling of the above exception, another exception occurred:

Traceback (most recent call last):
  File "/home/airflow/.local/lib/python3.7/site-packages/airflow/models/taskinstance.py", line 1962, in handle_failure
    self.email_alert(error, task)
  File "/home/airflow/.local/lib/python3.7/site-packages/airflow/models/taskinstance.py", line 2348, in email_alert
    send_email(task.email, subject, html_content_err)
  File "/home/airflow/.local/lib/python3.7/site-packages/airflow/utils/email.py", line 71, in send_email
    **kwargs,
  File "/home/airflow/.local/lib/python3.7/site-packages/airflow/utils/email.py", line 119, in send_email_smtp
    send_mime_email(e_from=mail_from, e_to=recipients, mime_msg=msg, conn_id=conn_id, dryrun=dryrun)
  File "/home/airflow/.local/lib/python3.7/site-packages/airflow/utils/email.py", line 230, in send_mime_email
    smtp_conn = _get_smtp_connection(smtp_host, smtp_port, smtp_timeout, smtp_ssl)
  File "/home/airflow/.local/lib/python3.7/site-packages/airflow/utils/email.py", line 264, in _get_smtp_connection
    else smtplib.SMTP(host=host, port=port, timeout=timeout)
  File "/usr/local/lib/python3.7/smtplib.py", line 251, in __init__
    (code, msg) = self.connect(host, port)
  File "/usr/local/lib/python3.7/smtplib.py", line 336, in connect
    self.sock = self._get_socket(host, port, self.timeout)
  File "/usr/local/lib/python3.7/smtplib.py", line 307, in _get_socket
    self.source_address)
  File "/usr/local/lib/python3.7/socket.py", line 728, in create_connection
    raise err
  File "/usr/local/lib/python3.7/socket.py", line 716, in create_connection
    sock.connect(sa)
OSError: [Errno 99] Cannot assign requested address
[2023-12-02 17:19:08,644] {standard_task_runner.py:97} ERROR - Failed to execute job 2 for task extract_data_from_fixed_width (Bash command failed. The command returned a non-zero exit code 2.; 1951)
[2023-12-02 17:19:08,701] {local_task_job.py:156} INFO - Task exited with return code 1
[2023-12-02 17:19:08,929] {local_task_job.py:273} INFO - 0 downstream tasks scheduled from follow-on schedule check
